Workbook

Sheet Sheet1
A1: LANo | B1: LAName | C1: 1 | D1: 2 | E1: 3 | F1: 4 | G1: 5 | H1: 6 | I1: 7 | J1: 8 | K1: 9 | L1: 10
A2: 301 | B2: Barking and Dagenham | C2: Enfield | D2: Luton | E2: Hounslow | F2: Sandwell | G2: Wolverhampton | H2: Ealing | I2: Brent | J2: Hillingdon | K2: Peterborough | L2: Greenwich
A3: 302 | B3: Barnet | C3: Waltham Forest | D3: Reading | E3: Harrow | F3: Redbridge | G3: Merton | H3: Croydon | I3: Lewisham | J3: Hillingdon | K3: Haringey | L3: Ealing
A4: 370 | B4: Barnsley | C4: Rotherham | D4: Wakefield | E4: Tameside | F4: Doncaster | G4: Dudley | H4: Telford and Wrekin | I4: Durham | J4: Gateshead | K4: Redcar and Cleveland | L4: Sunderland
A5: 800 | B5: Bath and North East Somerset | C5: York | D5: Trafford | E5: Hertfordshire | F5: Stockport | G5: West Sussex | H5: Kingston upon Thames | I5: Buckinghamshire | J5: Oxfordshire | K5: Cambridgeshire | L5: Gloucestershire
A6: 822 | B6: Bedford Borough | C6: Bexley | D6: Milton Keynes | E6: West Northamptonshire | F6: Havering | G6: Warwickshire | H6: Bournemouth, Christchurch and Poole | I6: Kent | J6: Suffolk | K6: Essex | L6: Swindon
A7: 303 | B7: Bexley | C7: Havering | D7: Bedford Borough | E7: Kent | F7: Essex | G7: Thurrock | H7: Medway | I7: Milton Keynes | J7: Swindon | K7: Bournemouth, Christchurch and Poole | L7: Bury
A8: 330 | B8: Birmingham | C8: Nottingham | D8: Manchester | E8: Bradford | F8: Newcastle upon Tyne | G8: Oldham | H8: Blackburn with Darwen | I8: Sheffield | J8: Middlesbrough | K8: Southampton | L8: Salford
A9: 889 | B9: Blackburn with Darwen | C9: Bradford | D9: Oldham | E9: Bolton | F9: Derby | G9: Rochdale | H9: Walsall | I9: Sheffield | J9: Stoke-on-Trent | K9: Birmingham | L9: Kirklees
A10: 890 | B10: Blackpool | C10: Hartlepool | D10: Middlesbrough | E10: Sunderland | F10: Liverpool | G10: South Tyneside | H10: Redcar and Cleveland | I10: Rochdale | J10: Torbay | K10: Salford | L10: Stoke-on-Trent
A11: 350 | B11: Bolton | C11: Rochdale | D11: Derby | E11: Oldham | F11: Tameside | G11: Walsall | H11: Salford | I11: Blackburn with Darwen | J11: Coventry | K11: Sheffield | L11: Peterborough
A12: 837 | B12: Bournemouth
A13: 839 | B13: Bournemouth, Christchurch and Poole | C13: Bedford Borough | D13: Southend-on-Sea | E13: Kent | F13: Devon | G13: Milton Keynes | H13: Bexley | I13: West Sussex | J13: Norfolk | K13: East Sussex | L13: Essex
A14: 867 | B14: Bracknell Forest | C14: Hertfordshire | D14: Hampshire | E14: Buckinghamshire | F14: Oxfordshire | G14: West Berkshire | H14: West Sussex | I14: South Gloucestershire | J14: Central Bedfordshire | K14: Gloucestershire | L14: Wiltshire
A15: 380 | B15: Bradford | C15: Blackburn with Darwen | D15: Birmingham | E15: Oldham | F15: Sheffield | G15: Derby | H15: Rochdale | I15: Bolton | J15: Walsall | K15: Sandwell | L15: Kirklees
A16: 304 | B16: Brent | C16: Ealing | D16: Newham | E16: Hounslow | F16: Haringey | G16: Luton | H16: Slough | I16: Barking and Dagenham | J16: Enfield | K16: Waltham Forest | L16: Redbridge
A17: 846 | B17: Brighton and Hove | C17: Bristol, City of | D17: Southend-on-Sea | E17: Barnet | F17: Kingston upon Thames | G17: Bath and North East Somerset | H17: Leeds | I17: Lewisham | J17: Milton Keynes | K17: Wandsworth | L17: York
A18: 801 | B18: Bristol, City of | C18: Brighton and Hove | D18: Leeds | E18: Southend-on-Sea | F18: Sheffield | G18: Milton Keynes | H18: Portsmouth | I18: Reading | J18: Barnet | K18: Bournemouth, Christchurch and Poole | L18: Kirklees
A19: 305 | B19: Bromley | C19: Hertfordshire | D19: Trafford | E19: Buckinghamshire | F19: West Berkshire | G19: Bracknell Forest | H19: Oxfordshire | I19: Hampshire | J19: Windsor and Maidenhead | K19: Solihull | L19: Surrey
A20: 825 | B20: Buckinghamshire | C20: Oxfordshire | D20: Hertfordshire | E20: West Berkshire | F20: Surrey | G20: Cambridgeshire | H20: Bracknell Forest | I20: Central Bedfordshire | J20: Windsor and Maidenhead | K20: Trafford | L20: Hampshire
A21: 351 | B21: Bury | C21: Lancashire | D21: Cornwall | E21: North Tyneside | F21: Kent | G21: Dudley | H21: Nottinghamshire | I21: Stockton-on-Tees | J21: Norfolk | K21: Medway | L21: Bexley
A22: 381 | B22: Calderdale | C22: Bournemouth, Christchurch and Poole | D22: East Sussex | E22: Devon | F22: Isle of Wight | G22: Norfolk | H22: Southend-on-Sea | I22: Bolton | J22: Northumberland | K22: Leeds | L22: Stockport
A23: 873 | B23: Cambridgeshire | C23: Oxfordshire | D23: Hertfordshire | E23: Buckinghamshire | F23: South Gloucestershire | G23: Warwickshire | H23: Gloucestershire | I23: West Sussex | J23: Central Bedfordshire | K23: Hampshire | L23: West Berkshire
A24: 202 | B24: Camden | C24: Islington | D24: Westminster | E24: Hammersmith and Fulham | F24: Southwark | G24: Lambeth | H24: Kensington and Chelsea | I24: Lewisham | J24: Haringey | K24: Hackney | L24: Barnet
... A31: 306 | B31: Croydon | C31: Lewisham | D31: Waltham Forest | E31: Leeds | F31: Reading | G31: Milton Keynes | H31: Southend-on-Sea | I31: Barnet | J31: Southampton | K31: Salford | L31: Greenwich
A32: 909 | B32: Cumbria
A33: 942 | B33: Cumberland | C33: Westmorland and Furness | D33: Lincolnshire | E33: Herefordshire | F33: Lancashire | G33: North Lincolnshire | H33: Wakefield | I33: Staffordshire | J33: Northumberland | K33: Doncaster | L33: Barnsley
A34: 841 | B34: Darlington | C34: Gateshead | D34: Stockton-on-Tees | E34: Dudley | F34: Wakefield | G34: Lancashire | H34: Telford and Wrekin | I34: Rotherham | J34: Tameside | K34: Durham | L34: Doncaster
A35: 831 | B35: Derby | C35: Coventry | D35: Bolton | E35: Walsall | F35: Southampton | G35: Kirklees | H35: Peterborough | I35: Rochdale | J35: Sheffield | K35: Tameside | L35: Stoke-on-Trent
A36: 830 | B36: Derbyshire | C36: Nottinghamshire | D36: Somerset | E36: Suffolk | F36: Norfolk | G36: Staffordshire | H36: Devon | I36: Shropshire | J36: Northumberland | K36: Dorset | L36: Worcestershire
A37: 878 | B37: Devon | C37: East Sussex | D37: Dorset | E37: Norfolk | F37: Kent | G37: Somerset | H37: Suffolk | I37: West Sussex | J37: Derbyshire | K37: Essex | L37: Worcestershire
A38: 371 | B38: Doncaster | C38: Rotherham | D38: Barnsley | E38: Wakefield | F38: Telford and Wrekin | G38: Tameside | H38: North East Lincolnshire | I38: Walsall | J38: Stoke-on-Trent | K38: Rochdale | L38: North Lincolnshire
A39: 838 | B39: Dorset | C39: Somerset | D39: Devon | E39: Shropshire | F39: Suffolk | G39: Worcestershire | H39: Essex | I39: Derbyshire | J39: Kent | K39: West Sussex | L39: North Yorkshire
A40: 332 | B40: Dudley | C40: Wakefield | D40: Telford and Wrekin | E40: Stockton-on-Tees | F40: Rotherham | G40: Barnsley | H40: Medway | I40: Tameside | J40: Lancashire | K40: Darlington | L40: Lincolnshire
A41: 840 | B41: Durham | C41: Halton | D41: Wirral | E41: Gateshead | F41: Redcar and Cleveland | G41: Rotherham | H41: Barnsley | I41: Sunderland | J41: South Tyneside | K41: Stockton-on-Tees | L41: Darlington
A42: 307 | B42: Ealing | C42: Hounslow | D42: Redbridge | E42: Hillingdon | F42: Waltham Forest | G42: Brent | H42: Haringey | I42: Harrow | J42: Slough | K42: Luton | L42: Barnet
A43: 811 | B43: East Riding of Yorkshire | C43: Staffordshire | D43: Shropshire | E43: North Yorkshire | F43: Warrington | G43: Leicestershire | H43: Somerset | I43: Herefordshire | J43: Westmorland and Furness | K43: Warwickshire | L43: Derbyshire
A44: 845 | B44: East Sussex | C44: Devon | D44: Kent | E44: Cornwall | F44: Norfolk | G44: Essex | H44: Bury | I44: Dorset | J44: West Sussex | K44: Northumberland | L44: Bournemouth, Christchurch and Poole
... A93: 815 | B93: North Yorkshire | C93: Shropshire | D93: Cheshire East | E93: East Riding of Yorkshire | F93: Staffordshire | G93: Gloucestershire | H93: Warrington | I93: Warwickshire | J93: Herefordshire | K93: Wiltshire | L93: Somerset
A94: 928 | B94: Northamptonshire
...

Sheet Stats Neighbours
A1: LANo | B1: LAName | C1: Statistical Neighbours | D1: Stats Neighbour LA Code
A2: 301 | B2: Barking and Dagenham | C2: Enfield | D2: =_xlfn.XLOOKUP(Table1_1[[#This Row],[Statistical Neighbours]], Sheet1!B:B, Sheet1!A:A, "Not Found") -> 308
A3: 301 | B3: Barking and Dagenham | C3: Luton | D3: =_xlfn.XLOOKUP(Table1_1[[#This Row],[Statistical Neighbours]], Sheet1!B:B, Sheet1!A:A, "Not Found") -> 821
A4: 301 | B4: Barking and Dagenham | C4: Hounslow | D4: =_xlfn.XLOOKUP(Table1_1[[#This Row],[Statistical Neighbours]], Sheet1!B:B, Sheet1!A:A, "Not Found") -> 313
A5: 301 | B5: Barking and Dagenham | C5: Sandwell | D5: =_xlfn.XLOOKUP(Table1_1[[#This Row],[Statistical Neighbours]], Sheet1!B:B, Sheet1!A:A, "Not Found") -> 333
A6: 301 | B6: Barking and Dagenham | C6: Wolverhampton | D6: =_xlfn.XLOOKUP(Table1_1[[#This Row],[Statistical Neighbours]], Sheet1!B:B, Sheet1!A:A, "Not Found") -> 336
A7: 301 | B7: Barking and Dagenham | C7: Ealing | D7: =_xlfn.XLOOKUP(Table1_1[[#This Row],[Statistical Neighbours]], Sheet1!B:B, Sheet1!A:A, "Not Found") -> 307
A8: 301 | B8: Barking and Dagenham | C8: Brent | D8: =_xlfn.XLOOKUP(Table1_1[[#This Row],[Statistical Neighbours]], Sheet1!B:B, Sheet1!A:A, "Not Found") -> 304
A9: 301 | B9: Barking and Dagenham | C9: Hillingdon | D9: =_xlfn.XLOOKUP(Table1_1[[#This Row],[Statistical Neighbours]], Sheet1!B:B, Sheet1!A:A, "Not Found") -> 312
A10: 301 | B10: Barking and Dagenham | C10: Peterborough | D10: =_xlfn.XLOOKUP(Table1_1[[#This Row],[Statistical Neighbours]], Sheet1!B:B, Sheet1!A:A, "Not Found") -> 874
A11: 301 | B11: Barking and Dagenham | C11: Barking and Dagenham | D11: =_xlfn.XLOOKUP(Table1_1[[#This Row],[Statistical Neighbours]], Sheet1!B:B, Sheet1!A:A, "Not Found") -> 301
A12: 301 | B12: Barking and Dagenham | C12: Greenwich | D12: =_xlfn.XLOOKUP(Table1_1[[#This Row],[Statistical Neighbours]], Sheet1!B:B, Sheet1!A:A, "Not Found") -> 203
A13: 302 | B13: Barnet | C13: Waltham Forest | D13: =_xlfn.XLOOKUP(Table1_1[[#This Row],[Statistical Neighbours]], Sheet1!B:B, Sheet1!A:A, "Not Found") -> 320
... A1695: 816 | B1695: York | C1695: Stockport | D1695: =_xlfn.XLOOKUP(Table1_1[[#This Row],[Statistical Neighbours]], Sheet1!B:B, Sheet1!A:A, "Not Found") -> 356

Sheet Regions and MCA
A1: LA Code | B1: LA Name | C1: Region | D1: Mayoral Combined Authority | E1: Type of Local Authority
A2: 301 | B2: Barking and Dagenham | C2: London | E2: London borough
A3: 302 | B3: Barnet | C3: London | E3: London borough
A4: 370 | B4: Barnsley | C4: Yorkshire and the Humber | D4: South Yorkshire - Combined Authority | E4: Metropolitan borough council
A5: 800 | B5: Bath and North East Somerset | C5: South West | D5: West of England - Combined Authority | E5: Unitary
A6: 822 | B6: Bedford Borough | C6: East of England | D6: South Midlands - Proposed Combined Authority | E6: Unitary
A7: 303 | B7: Bexley | C7: London | E7: London borough
A8: 330 | B8: Birmingham | C8: West Midlands | D8: West Midlands - Combined Authority | E8: Metropolitan borough council
A9: 889 | B9: Blackburn with Darwen | C9: North West | D9: Lancashire - Combined Authority | E9: Unitary
A10: 890 | B10: Blackpool | C10: North West | D10: Lancashire - Combined Authority | E10: Unitary
A11: 350 | B11: Bolton | C11: North West | D11: Greater Manchester - Combined Authority | E11: Metropolitan borough council
A12: 839 | B12: Bournemouth, Christchurch and Poole | C12: South West | D12: Hampshire and the Solent - Proposed Combined Authority | E12: Unitary
A13: 867 | B13: Bracknell Forest | C13: South East | D13: Thames Valley - Proposed Combined Authority | E13: Unitary
A14: 380 | B14: Bradford | C14: Yorkshire and the Humber | D14: West Yorkshire - Combined Authority | E14: Metropolitan borough council
A15: 304 | B15: Brent | C15: London | E15: London borough
A16: 846 | B16: Brighton and Hove | C16: South East | D16: Sussex and Brighton - Proposed Combined Authority | E16: Unitary
A17: 801 | B17: Bristol, City of | C17: South West | D17: West of England - Combined Authority | E17: Unitary
A18: 305 | B18: Bromley | C18: London | E18: London borough
A19: 825 | B19: Buckinghamshire | C19: South East | D19: Thames Valley - Proposed Combined Authority | E19: County
A20: 351 | B20: Bury | C20: North West | D20: Greater Manchester - Combined Authority | E20: Metropolitan borough council
A21: 381 | B21: Calderdale | C21: Yorkshire and the Humber | D21: West Yorkshire - Combined Authority | E21: Metropolitan borough council
A22: 873 | B22: Cambridgeshire | C22: East of England | D22: Cambridgeshire and Peterborough - Combined Authority | E22: County
A23: 202 | B23: Camden | C23: London | E23: London borough
A24: 823 | B24: Central Bedfordshire | C24: East of England | D24: South Midlands - Proposed Combined Authority | E24: Unitary
A25: 895 | B25: Cheshire East | C25: North West | D25: Cheshire and Warrington - Proposed Combined Authority | E25: Unitary
A26: 896 | B26: Cheshire West and Chester | C26: North West | D26: Cheshire and Warrington - Proposed Combined Authority | E26: Unitary
A27: 201 | B27: City of London | C27: London | E27: City of London Corporation
A28: 908 | B28: Cornwall | C28: South West | E28: Unitary
A29: 331 | B29: Coventry | C29: West Midlands | D29: West Midlands - Combined Authority | E29: Metropolitan borough council
A30: 306 | B30: Croydon | C30: London | E30: London borough
A31: 942 | B31: Cumberland | C31: North West | D31: Cumbria - Proposed Combined Authority
A32: 909 | B32: Cumbria | C32: North West | E32: County
A33: 841 | B33: Darlington | C33: North East | D33: Tees Valley - Combined Authority | E33: Unitary
A34: 831 | B34: Derby | C34: East Midlands | D34: East Midlands - Combined Authority | E34: Unitary
A35: 830 | B35: Derbyshire | C35: East Midlands | D35: East Midlands - Combined Authority | E35: County
A36: 878 | B36: Devon | C36: South West | D36: Devon and Torbay - Combined Authority | E36: County
A37: 371 | B37: Doncaster | C37: Yorkshire and the Humber | D37: South Yorkshire - Combined Authority | E37: Metropolitan borough council
A38: 838 | B38: Dorset | C38: South West | D38: Heart of Wessex - Proposed Combined Authority | E38: County
A39: 332 | B39: Dudley | C39: West Midlands | D39: West Midlands - Combined Authority | E39: Metropolitan borough council
A40: 840 | B40: Durham | C40: North East | D40: North East - Combined Authority | E40: Unitary
...
